import React from 'react';
import { render, fireEvent } from '@testing-library/react-native';
import { ErrorBoundary, withErrorBoundary } from '../ErrorBoundary';
import { Text, TouchableOpacity } from 'react-native';

// Mock Alert
jest.mock('react-native', () => {
  const RN = jest.requireActual('react-native');
  return {
    ...RN,
    Alert: {
      alert: jest.fn(),
    },
  };
});

// Component that throws an error
const ThrowError = ({ shouldThrow }: { shouldThrow: boolean }) => {
  if (shouldThrow) {
    throw new Error('Test error');
  }
  return <Text>No error</Text>;
};

describe('ErrorBoundary', () => {
  // Suppress console.error for these tests
  const originalError = console.error;
  beforeAll(() => {
    console.error = jest.fn();
  });

  afterAll(() => {
    console.error = originalError;
  });

  beforeEach(() => {
    jest.clearAllMocks();
  });

  it('should render children when there is no error', () => {
    const { getByText } = render(
      <ErrorBoundary>
        <ThrowError shouldThrow={false} />
      </ErrorBoundary>
    );

    expect(getByText('No error')).toBeTruthy();
  });

  it('should render error UI when child component throws', () => {
    const { getByText } = render(
      <ErrorBoundary>
        <ThrowError shouldThrow={true} />
      </ErrorBoundary>
    );

    expect(getByText('Oops! ðŸŒ±')).toBeTruthy();
    expect(getByText('Something went wrong')).toBeTruthy();
    expect(getByText('Try Again')).toBeTruthy();
  });

  it('should call onError callback when error occurs', () => {
    const onError = jest.fn();
    
    render(
      <ErrorBoundary onError={onError}>
        <ThrowError shouldThrow={true} />
      </ErrorBoundary>
    );

    expect(onError).toHaveBeenCalledWith(
      expect.any(Error),
      expect.objectContaining({
        componentStack: expect.any(String),
      })
    );
  });

  it('should render custom fallback when provided', () => {
    const fallback = <Text>Custom error message</Text>;
    
    const { getByText } = render(
      <ErrorBoundary fallback={fallback}>
        <ThrowError shouldThrow={true} />
      </ErrorBoundary>
    );

    expect(getByText('Custom error message')).toBeTruthy();
  });

  it('should reset error state when retry is pressed', () => {
    const { getByText, rerender } = render(
      <ErrorBoundary>
        <ThrowError shouldThrow={true} />
      </ErrorBoundary>
    );

    // Error UI should be visible
    expect(getByText('Try Again')).toBeTruthy();

    // Press retry button
    fireEvent.press(getByText('Try Again'));

    // Re-render with no error
    rerender(
      <ErrorBoundary>
        <ThrowError shouldThrow={false} />
      </ErrorBoundary>
    );

    expect(getByText('No error')).toBeTruthy();
  });
});

describe('withErrorBoundary', () => {
  it('should wrap component with error boundary', () => {
    const TestComponent = () => <Text>Test Component</Text>;
    const WrappedComponent = withErrorBoundary(TestComponent);

    const { getByText } = render(<WrappedComponent />);
    expect(getByText('Test Component')).toBeTruthy();
  });

  it('should handle errors in wrapped component', () => {
    const WrappedComponent = withErrorBoundary(ThrowError);

    const { getByText } = render(<WrappedComponent shouldThrow={true} />);
    expect(getByText('Something went wrong')).toBeTruthy();
  });
});